<?xml version="1.0" ?>
<!-- =================================================================================== -->
<!-- |    This document was autogenerated by xacro from robot.xacro                    | -->
<!-- |    EDITING THIS FILE BY HAND IS NOT RECOMMENDED                                 | -->
<!-- =================================================================================== -->
<robot name="VX300" xmlns:xacro="http://www.ros.org/wiki/xacro">
  <material name="black">
    <color rgba="0.0 0.0 0.0 1.0"/>
  </material>
  <material name="blue">
    <color rgba="0.0 0.0 0.8 1.0"/>
  </material>
  <material name="green">
    <color rgba="0.0 0.8 0.0 1.0"/>
  </material>
  <material name="grey">
    <color rgba="0.2 0.2 0.2 1.0"/>
  </material>
  <material name="silver">
    <color rgba="0.913725490196 0.913725490196 0.847058823529 1.0"/>
  </material>
  <material name="orange">
    <color rgba="1.0 0.423529411765 0.0392156862745 1.0"/>
  </material>
  <material name="brown">
    <color rgba="0.870588235294 0.811764705882 0.764705882353 1.0"/>
  </material>
  <material name="red">
    <color rgba="0.8 0.0 0.0 1.0"/>
  </material>
  <material name="white">
    <color rgba="1.0 1.0 1.0 1.0"/>
  </material>


  <material name="interbotix_black">
    <color rgba="0.4 0.4 0.4 1"/>
  </material>





  <link name="vx300/base_link">
    <visual>
      <origin rpy="0 0 1.57" xyz="0 0 0"/>
      <geometry>
        <mesh filename="package://vx300_meshes/base_link_new.stl" scale="0.001 0.001 0.001"/>
      </geometry>
      <material name="interbotix_black"/>
    </visual>
    <collision>
      <origin rpy="0 0 1.57" xyz="0 0 0"/>
      <geometry>
        <mesh filename="package://vx300_meshes/base_link_new.stl" scale="0.001 0.001 0.001"/>
      </geometry>
    </collision>
    <inertial>
      <origin rpy="0 0 1.57" xyz="-0.0534774000 -0.0005625750 0.0205961000"/>
      <mass value="0.969034" />
      <inertia ixx="0.0060240000" iyy="0.0017000000" izz="0.0071620000" ixy="0.0000471300" ixz="0.0000038510" iyz="-0.0000841500" />
    </inertial>
  </link>

  <joint name="waist" type="revolute">
    <axis xyz="0 0 1"/>
    <limit effort="10" lower="-3.141582653589793" upper="3.141582653589793" velocity="3.141592653589793"/>
    <origin rpy="0 0 0" xyz="0 0 0.079"/>
    <parent link="vx300/base_link"/>
    <child link="vx300/shoulder_link"/>
    <dynamics friction="0.1"/>
  </joint>

  <transmission name="trans_waist">
    <type>transmission_interface/SimpleTransmission</type>
    <joint name="waist">
      <hardwareInterface>hardware_interface/EffortJointInterface</hardwareInterface>
    </joint>
    <actuator name="waist_motor">
      <mechanicalReduction>1</mechanicalReduction>
    </actuator>
  </transmission>

  <link name="vx300/shoulder_link">
    <visual>
      <origin rpy="0 0 0" xyz="0 0 -0.003"/>
      <geometry>
        <mesh filename="package://vx300_meshes/shoulder.stl" scale="0.001 0.001 0.001"/>
      </geometry>
      <material name="interbotix_black"/>
    </visual>
    <collision>
      <origin rpy="0 0 0" xyz="0 0 -0.003"/>
      <geometry>
        <mesh filename="package://vx300_meshes/shoulder.stl" scale="0.001 0.001 0.001"/>
      </geometry>
    </collision>
    <inertial>
      <origin rpy="0 0 1.57" xyz="0.0002592330 -0.0000033552 0.0116129000"/>
      <mass value="0.798614" />
      <inertia ixx="0.0009388000" iyy="0.0011380000" izz="0.0012010000" ixy="-0.0000000010" ixz="-0.0000000191" iyz="0.0000059568" />
    </inertial>
  </link>

  <joint name="shoulder" type="revolute">
    <axis xyz="0 1 0"/>
    <limit effort="20" lower="-1.8500490071139892" upper="1.2566370614359172" velocity="3.141592653589793"/>
    <origin rpy="0 0 0" xyz="0 0 0.04805"/>
    <parent link="vx300/shoulder_link"/>
    <child link="vx300/upper_arm_link"/>
    <dynamics friction="0.1"/>
  </joint>

  <transmission name="trans_shoulder">
    <type>transmission_interface/SimpleTransmission</type>
    <joint name="shoulder">
      <hardwareInterface>hardware_interface/EffortJointInterface</hardwareInterface>
    </joint>
    <actuator name="shoulder_motor">
      <mechanicalReduction>1</mechanicalReduction>
    </actuator>
  </transmission>

  <link name="vx300/upper_arm_link">
    <visual>
      <origin rpy="0 0 1.57" xyz="0 0 0"/>
      <geometry>
        <mesh filename="package://vx300_meshes/VXA-300-M-3-UA.stl" scale="0.001 0.001 0.001"/>
      </geometry>
      <material name="interbotix_black"/>
    </visual>
    <collision>
      <origin rpy="0 0 1.57" xyz="0 0 0"/>
      <geometry>
        <mesh filename="package://vx300_meshes/VXA-300-M-3-UA.stl" scale="0.001 0.001 0.001"/>
      </geometry>
    </collision>
    <inertial>
      <origin rpy="0 0 1.57" xyz="0.0206949000 0.0000000004 0.2264590000"/>
      <mass value="0.792592" />
      <inertia ixx="0.0089250000" iyy="0.0089370000" izz="0.0009357000" ixy="0.0000000000" ixz="0.0000000000" iyz="0.0012010000" />
    </inertial>
  </link>

  <joint name="elbow" type="revolute">
    <axis xyz="0 1 0"/>
    <limit effort="15" lower="-1.7627825445142729" upper="1.6057029118347832" velocity="3.141592653589793"/>
    <origin rpy="0 0 0" xyz="0.05955 0 0.3"/>
    <parent link="vx300/upper_arm_link"/>
    <child link="vx300/forearm_link"/>
    <dynamics friction="0.1"/>
  </joint>

  <transmission name="trans_elbow">
    <type>transmission_interface/SimpleTransmission</type>
    <joint name="elbow">
      <hardwareInterface>hardware_interface/EffortJointInterface</hardwareInterface>
    </joint>
    <actuator name="elbow_motor">
      <mechanicalReduction>1</mechanicalReduction>
    </actuator>
  </transmission>

  <link name="vx300/forearm_link">
    <visual>
      <origin rpy="0 0 1.57" xyz="0 0 0"/>
      <geometry>
        <mesh filename="package://vx300_meshes/VXA-300-M-4-Forearm.stl" scale="0.001 0.001 0.001"/>
      </geometry>
      <material name="interbotix_black"/>
    </visual>
    <collision>
      <origin rpy="0 0 1.57" xyz="0 0 0"/>
      <geometry>
        <mesh filename="package://vx300_meshes/VXA-300-M-4-Forearm.stl" scale="0.001 0.001 0.001"/>
      </geometry>
    </collision>
    <inertial>
      <origin rpy="0 0 1.57" xyz="0.1812650000 -0.0002065037 0.0000000000"/>
      <mass value="0.544659" />
      <inertia ixx="0.0054470000" iyy="0.0002267000" izz="0.0055740000" ixy="-0.0000119800" ixz="0.0000000000" iyz="0.0000000000" />
    </inertial>
  </link>

  <joint name="wrist_angle" type="revolute">
    <axis xyz="0 1 0"/>
    <limit effort="5" lower="-1.8675022996339325" upper="2.234021442552742" velocity="3.141592653589793"/>
    <origin rpy="0 0 0" xyz="0.3 0 0"/>
    <parent link="vx300/forearm_link"/>
    <child link="vx300/wrist_link"/>
    <dynamics friction="0.1"/>
  </joint>

  <transmission name="trans_wrist_angle">
    <type>transmission_interface/SimpleTransmission</type>
    <joint name="wrist_angle">
      <hardwareInterface>hardware_interface/EffortJointInterface</hardwareInterface>
    </joint>
    <actuator name="wrist_angle_motor">
      <mechanicalReduction>1</mechanicalReduction>
    </actuator>
  </transmission>

  <link name="vx300/wrist_link">
    <visual>
      <origin rpy="0 3.14 1.57" xyz="0 0 0"/>
      <geometry>
        <mesh filename="package://vx300_meshes/VXA-300-M-5-Wrist.stl" scale="0.001 0.001 0.001"/>
      </geometry>
      <material name="interbotix_black"/>
    </visual>
    <collision>
      <origin rpy="0 3.14 1.57" xyz="0 0 0"/>
      <geometry>
        <mesh filename="package://vx300_meshes/VXA-300-M-5-Wrist.stl" scale="0.001 0.001 0.001"/>
      </geometry>
    </collision>
    <inertial>
      <origin rpy="0 3.14 1.57" xyz="0.0467430000 0.0000076652 -0.0105650000"/>
      <mass value="0.115395" />
      <inertia ixx="0.0000463100" iyy="0.0000451400" izz="0.0000527000" ixy="0.0000000195" ixz="0.0000000023" iyz="0.0000042002" />
    </inertial>
  </link>

  <joint name="wrist_rotate" type="revolute">
    <axis xyz="1 0 0"/>
    <limit effort="1" lower="-3.141582653589793" upper="3.141582653589793" velocity="3.141592653589793"/>
    <origin rpy="0 0 0" xyz="0.069744 0 0"/>
    <parent link="vx300/wrist_link"/>
    <child link="vx300/gripper_link"/>
    <dynamics friction="0.1"/>
  </joint>

  <transmission name="trans_wrist_rotate">
    <type>transmission_interface/SimpleTransmission</type>
    <joint name="wrist_rotate">
      <hardwareInterface>hardware_interface/EffortJointInterface</hardwareInterface>
    </joint>
    <actuator name="wrist_rotate_motor">
      <mechanicalReduction>1</mechanicalReduction>
    </actuator>
  </transmission>

  <link name="vx300/gripper_link">
    <visual>
      <origin rpy="0 0 1.57" xyz="-0.02 0 0"/>
      <geometry>
        <mesh filename="package://vx300_meshes/gripper_and_camera.stl" scale="0.001 0.001 0.001"/>
      </geometry>
      <material name="black"/>
    </visual>
    <collision>
      <origin rpy="0 0 1.57" xyz="-0.02 0 0"/>
      <geometry>
        <mesh filename="package://vx300_meshes/gripper_and_camera.stl" scale="0.001 0.001 0.001"/>
      </geometry>
    </collision>
    <inertial>
      <origin rpy="0 0 1.57" xyz="0.0230010000 0.0000000000 0.0115230000"/>
      <mass value="0.000001" />
      <inertia ixx="0.0000326800" iyy="0.0000243600" izz="0.0000211900" ixy="0.0000000000" ixz="0.0000000000" iyz="0.0000002785" />
    </inertial>
  </link>

  <joint name="ee_arm" type="fixed">
    <axis xyz="1 0 0"/>
    <origin rpy="0 0 0" xyz="0.042825 0 0"/>
    <parent link="vx300/gripper_link"/>
    <child link="vx300/ee_arm_link"/>
  </joint>

  <link name="vx300/ee_arm_link">
    <inertial>
      <mass value="0.001" />
      <inertia ixx="0.0001" iyy="0.0001" izz="0.0001" ixy="0" ixz="0" iyz="0" />
    </inertial>
  </link>

  <joint name="gripper" type="fixed">
    <axis xyz="1 0 0"/>
    <limit effort="1" velocity="3.141592653589793"/>
    <origin rpy="0 0 0" xyz="0.005675 0 0"/>
    <parent link="vx300/ee_arm_link"/>
    <child link="vx300/gripper_prop_link"/>
    <dynamics friction="0.1"/>
  </joint>

  <transmission name="trans_gripper">
    <type>transmission_interface/SimpleTransmission</type>
    <joint name="gripper">
      <hardwareInterface>hardware_interface/EffortJointInterface</hardwareInterface>
    </joint>
    <actuator name="gripper_motor">
      <mechanicalReduction>1</mechanicalReduction>
    </actuator>
  </transmission>

  <link name="vx300/gripper_prop_link">
    <visual>
      <origin rpy="0 0 1.57" xyz="-0.0685 0 0"/>
      <geometry>
        <mesh filename="package://vx300_meshes/VXA-300-M-7-Gripper-Prop.stl" scale="0.001 0.001 0.001"/>
      </geometry>
      <material name="interbotix_black"/>
    </visual>
    <collision>
      <origin rpy="0 0 1.57" xyz="-0.0685 0 0"/>
      <geometry>
        <mesh filename="package://vx300_meshes/VXA-300-M-7-Gripper-Prop.stl" scale="0.001 0.001 0.001"/>
      </geometry>
    </collision>
    <inertial>
      <origin rpy="0 0 1.57" xyz="0.0023780000 0.0000000285 0.0000000000"/>
      <mass value="0.008009" />
      <inertia ixx="0.0000020386" iyy="0.0000042979" izz="0.0000023796" ixy="0.0000000000" ixz="0.0000006559" iyz="0.0000000000" />
    </inertial>
  </link>

  <!-- If the default gripper bar is being used, then also add the gripper bar -->

  <!--xacro:if value="$(arg use_default_gripper_bar)"-->

    <joint name="gripper_bar" type="fixed">
      <axis xyz="1 0 0"/>
      <origin rpy="0 0 0" xyz="0 0 0"/>
      <parent link="vx300/ee_arm_link"/>
      <child link="vx300/gripper_bar_link"/>
    </joint>

    <link name="vx300/gripper_bar_link">
      <visual>
        <origin rpy="0 0 1.57" xyz="-0.063 0 0"/>
        <geometry>
          <mesh filename="package://vx300_meshes/VXA-300-M-8-Gripper-Bar.stl" scale="0.001 0.001 0.001"/>
        </geometry>
        <material name="interbotix_black"/>
      </visual>
      <collision>
        <origin rpy="0 0 1.57" xyz="-0.063 0 0"/>
        <geometry>
          <mesh filename="package://vx300_meshes/VXA-300-M-8-Gripper-Bar.stl" scale="0.001 0.001 0.001"/>
        </geometry>
      </collision>
      <inertial>
        <origin rpy="0 0 1.57" xyz="0.0067940000 -0.0000004272 -0.0007760000"/>
        <mass value="0.150986" />
        <inertia ixx="0.0000789500" iyy="0.0003283000" izz="0.0003095000" ixy="-0.0000000012" ixz="0.0000001341" iyz="0.0000017465" />
      </inertial>
    </link>

    <joint name="ee_bar" type="fixed">
      <axis xyz="1 0 0"/>
      <origin rpy="0 0 0" xyz="0.025875 0 0"/>
      <parent link="vx300/gripper_bar_link"/>
      <child link="vx300/fingers_link"/>
    </joint>

    <link name="vx300/fingers_link">
      <inertial>
        <mass value="0.001" />
        <inertia ixx="0.0001" iyy="0.0001" izz="0.0001" ixy="0" ixz="0" iyz="0" />
      </inertial>
    </link>

    <!-- If the default gripper fingers are being used, add those as well -->

    <!--xacro:if value="$(arg use_default_gripper_fingers)"-->

      <joint name="left_finger" type="prismatic">
        <axis xyz="0 1 0"/>
        <limit effort="10" lower="0.021" upper="0.057" velocity="1"/>
        <origin rpy="0 0 0" xyz="0 0 0"/>
        <parent link="vx300/fingers_link"/>
        <child link="vx300/left_finger_link"/>
      </joint>

      <transmission name="trans_left_finger">
        <type>transmission_interface/SimpleTransmission</type>
        <joint name="left_finger">
          <hardwareInterface>hardware_interface/EffortJointInterface</hardwareInterface>
        </joint>
        <actuator name="left_finger_motor">
          <mechanicalReduction>1</mechanicalReduction>
        </actuator>
      </transmission>

      <link name="vx300/left_finger_link">
        <visual>
          <origin rpy="1.57 -3.14 1.57" xyz="-0.0404 -0.0575 0"/>
          <geometry>
            <mesh filename="package://vx300_meshes/VXA-300-M-9-Finger.stl" scale="0.001 0.001 0.001"/>
          </geometry>
          <material name="interbotix_black"/>
        </visual>
        <collision>
          <origin rpy="1.57 -3.14 1.57" xyz="-0.0404 -0.0575 0"/>
          <geometry>
            <mesh filename="package://vx300_meshes/VXA-300-M-9-Finger.stl" scale="0.001 0.001 0.001"/>
          </geometry>
        </collision>
        <inertial>
          <origin rpy="3.14 3.14 1.57" xyz="0.0173440000 -0.0060692000 0.0000000000"/>
          <mass value="0.034796" />
          <inertia ixx="0.0000243300" iyy="0.0000125500" izz="0.0000141700" ixy="-0.0000024004" ixz="0.0000000000" iyz="0.0000000000" />
        </inertial>
      </link>

      <joint name="right_finger" type="prismatic">
        <axis xyz="0 1 0"/>
        <limit effort="10" lower="-0.057" upper="-0.021" velocity="1"/>
        <origin rpy="0 0 0" xyz="0 0 0"/>
        <parent link="vx300/fingers_link"/>
        <child link="vx300/right_finger_link"/>
        <xacro:unless value="$(arg load_gazebo_configs)">
          <mimic joint="left_finger" multiplier="-1" offset="0"/>
        </xacro:unless>
      </joint>

      <transmission name="trans_right_finger">
        <type>transmission_interface/SimpleTransmission</type>
        <joint name="right_finger">
          <hardwareInterface>hardware_interface/EffortJointInterface</hardwareInterface>
        </joint>
        <actuator name="right_finger_motor">
          <mechanicalReduction>1</mechanicalReduction>
        </actuator>
      </transmission>

      <link name="vx300/right_finger_link">
        <visual>
          <origin rpy="-1.57 3.14 -1.57" xyz="-0.0404 0.0575 0"/>
          <geometry>
            <mesh filename="package://vx300_meshes/VXA-300-M-9-Finger.stl" scale="0.001 0.001 0.001"/>
          </geometry>
          <material name="interbotix_black"/>
        </visual>
        <collision>
          <origin rpy="-1.57 3.14 -1.57" xyz="-0.0404 0.0575 0"/>
          <geometry>
            <mesh filename="package://vx300_meshes/VXA-300-M-9-Finger.stl" scale="0.001 0.001 0.001"/>
          </geometry>
        </collision>
        <inertial>
          <origin rpy="0 3.14 1.57" xyz="0.0173440000 0.0060692000  0.0000000000"/>
          <mass value="0.034796" />
          <inertia ixx="0.0000243300" iyy="0.0000125500" izz="0.0000141700" ixy="0.0000024001" ixz="0.0000000000" iyz="0.0000000000" />
        </inertial>
      </link>

      <joint name="ee_gripper" type="fixed">
        <axis xyz="1 0 0"/>
        <origin rpy="0 0 0" xyz="0.0385 0 0"/>
        <parent link="vx300/fingers_link"/>
        <child link="vx300/ee_gripper_link"/>
      </joint>

      <link name="vx300/ee_gripper_link">
        <inertial>
          <mass value="0.001" />
          <inertia ixx="0.0001" iyy="0.0001" izz="0.0001" ixy="0" ixz="0" iyz="0" />
        </inertial>
      </link>
</robot>

